<?xml version="1.0"?>

<robot name="spot">
  <link name="base_link">
  </link>

  <joint name="joint1" type="revolute">
    <origin xyz="0.292 0.0 0.188" rpy="0 0 0"/>
    <axis xyz="0 0 1"/>
    <parent link="base_link"/>
    <child link="link1"/>
    <limit effort="1000" velocity="1000.00" lower="-2.61799387799149441136" upper="3.14159265358979311599"/>
  </joint>

  <link name="link1">
  </link>
  
  <joint name="joint2" type="revolute">
    <origin xyz="0.0 0.0 0.0" rpy="0 0 0"/>
    <axis xyz="0 1 0"/>
    <parent link="link1"/>
    <child link="link2"/>
    <limit effort="1000" velocity="1000.00" lower="-3.14159265358979311599" upper="0.52359877559829881565"/>
  </joint>

  <link name="link2">
  </link>

  <joint name="joint2a" type="fixed">
    <origin xyz="0.0 0.0 0.0" rpy="0 0 0"/>
    <axis xyz="1 0 0"/>
    <parent link="link2"/>
    <child link="link3"/>
    <!--limit effort="1000" velocity="1000.00" lower="-1e6" upper="1e6"/-->
  </joint>
  
  <link name="link3">
  </link>

  <joint name="joint3" type="revolute">
    <origin xyz="0.3385 0 0" rpy="0 0 0"/>
    <axis xyz="0 1 0"/>
    <parent link="link3"/>
    <child link="link4"/>
     <limit effort="1000" velocity="1000.00" lower="0" upper="3.14159265358979311599"/>
  </joint>
  
  <link name="link4">
  </link>
  
  <joint name="joint4" type="revolute">
    <origin xyz="0.40330 0.0 0.0750" rpy="0 0 0"/>
    <axis xyz="1 0 0"/>
    <parent link="link4"/>
    <child link="link5"/>
     <limit effort="1000" velocity="1000.00" lower="-2.79252680319092716487" upper="2.79252680319092716487"/>
  </joint>
  
  <link name="link5">
  </link>
  
  <joint name="joint5" type="revolute">
    <origin xyz="0.0 0.0 0.0" rpy="0 0 0"/>
    <axis xyz="0 1 0"/>
    <parent link="link5"/>
    <child link="link6"/>
    <limit effort="1000" velocity="1000.00" lower="-1.83259571459404613236" upper="1.83259571459404613236"/>
  </joint>
  
  <link name="link6">
  </link>
  
  <joint name="joint6" type="revolute">
    <origin xyz="0.0 0.0 0.0" rpy="0 0 0"/>
    <axis xyz="1 0 0"/>
    <parent link="link6"/>
    <child link="gripper"/>
     <limit effort="1000" velocity="1000.00" lower="-2.87979326579064354163" upper="2.87979326579064354163"/>
  </joint>
  
  <link name="gripper">
    <visual>
      <origin xyz="0 0 0" rpy="0 0 0"/>
      <geometry>
        <mesh filename="link_models/arm0.link_wr1.obj.dae"/>
      </geometry>
      <material name="arm0.link_wr1"> <color rgba="0.2 0.2 0.2 1"/></material>    
    </visual>
  </link>
  
  <joint name="arm0.f1x" type="revolute">
    <origin xyz="0.11745 0 0.014820" rpy="0 0 0"/>
    <axis xyz="0.0 1.0 0.0"/>
    <parent link="gripper"/>
    <child link="finger"/>
     <limit effort="1000" velocity="1000.00" lower="-1.57" upper="0.0"/>
  </joint>

  <link name="finger">
  </link>

</robot>
