<?xml version="1.0" ?>
<!-- =================================================================================== -->
<!-- |    This document was autogenerated by xacro from spot_ws/src/Spot-Arm/spot_arm_description/urdf/spot_arm.xacro | -->
<!-- |    EDITING THIS FILE BY HAND IS NOT RECOMMENDED                                 | -->
<!-- =================================================================================== -->
<robot name="spot_arm">
  <link name="base_link">
  </link>
  <joint name="j0" type="revolute">
    <origin rpy="0 0 0" xyz="0.0 0.0 0.065"/>
    <parent link="base_link"/>
    <child link="Part0_1"/>
    <axis xyz="0.0 0.0 1.0"/>
    <limit effort="100" lower="-3.141593" upper="2.617994" velocity="100"/>
  </joint>
  <link name="Part0_1">
  </link>
  <joint name="j1" type="revolute">
    <origin rpy="3.1415 0 0" xyz="0.015 0.0 0.05"/>
    <parent link="Part0_1"/>
    <child link="Part1_1"/>
    <axis xyz="-1.0 0.0 0.0"/>
    <limit effort="100" lower="-0.523598" upper="3.1415926" velocity="100"/>
  </joint>
  <link name="Part1_1">
  </link>
  <joint name="j2" type="revolute">
    <origin rpy="0 0 0" xyz="0.002 0.3125 0.0"/>
    <parent link="Part1_1"/>
    <child link="Part2_1"/>
    <axis xyz="1.0 0.0 0.0"/>
    <limit effort="100" lower="0.0" upper="2.96706" velocity="100"/>
  </joint>
  <link name="Part2_1">
  </link>
  <joint name="j3" type="revolute">
    <origin rpy="0 0 0" xyz="-0.018 0.138 -0.0675"/>
    <parent link="Part2_1"/>
    <child link="Part3_1"/>
    <axis xyz="0.0 1.0 0.0"/>
    <limit effort="100" lower="-2.879793" upper="2.879793" velocity="100"/>
  </joint>
  <link name="Part3_1">
  </link>
  <joint name="j4" type="revolute">
    <origin rpy="0 0 0" xyz="-0.0475 0.24809 0.0"/>
    <parent link="Part3_1"/>
    <child link="Part4_1"/>
    <axis xyz="1.0 0.0 0.0"/>
    <limit effort="100" lower="-1.8326" upper="1.8326" velocity="100"/>
  </joint>
  <link name="Part4_1">
  </link>
  <joint name="j5" type="revolute">
    <origin rpy="0 0 0" xyz="0.04 0.081 0.0"/>
    <parent link="Part4_1"/>
    <child link="gripper_1"/>
    <axis xyz="-0.0 1.0 0.0"/>
    <limit effort="100" lower="-2.96706" upper="2.96706" velocity="100"/>
  </joint>
  <link name="gripper_1">
  </link>
  <joint name="j6" type="revolute">
    <origin rpy="0 0 0" xyz="0 0.043915 -0.029"/>
    <parent link="gripper_1"/>
    <child link="finger_1"/>
    <axis xyz="1.0 -0.0 0.0"/>
    <limit effort="100" lower="-1.396263" upper="0.349066" velocity="100"/>
  </joint>
  <link name="finger_1">
  </link>
</robot>
