<?xml version="1.0" ?>
<!-- =================================================================================== -->
<!-- |    This document was autogenerated by xacro from Dynamixel_spot_arm.xacro       | -->
<!-- |    EDITING THIS FILE BY HAND IS NOT RECOMMENDED                                 | -->
<!-- =================================================================================== -->
<robot name="Dynamixel_spot_arm">
  <material name="silver">
    <color rgba="0.700 0.700 0.700 1.000"/>
  </material>
  <transmission name="Rev1_tran">
    <type>transmission_interface/SimpleTransmission</type>
    <joint name="Rev1">
      <hardwareInterface>hardware_interface/EffortJointInterface</hardwareInterface>
    </joint>
    <actuator name="Rev1_actr">
      <hardwareInterface>hardware_interface/EffortJointInterface</hardwareInterface>
      <mechanicalReduction>1</mechanicalReduction>
    </actuator>
  </transmission>
  <transmission name="Rev2_tran">
    <type>transmission_interface/SimpleTransmission</type>
    <joint name="Rev2">
      <hardwareInterface>hardware_interface/EffortJointInterface</hardwareInterface>
    </joint>
    <actuator name="Rev2_actr">
      <hardwareInterface>hardware_interface/EffortJointInterface</hardwareInterface>
      <mechanicalReduction>1</mechanicalReduction>
    </actuator>
  </transmission>
  <transmission name="Rev3_tran">
    <type>transmission_interface/SimpleTransmission</type>
    <joint name="Rev3">
      <hardwareInterface>hardware_interface/EffortJointInterface</hardwareInterface>
    </joint>
    <actuator name="Rev3_actr">
      <hardwareInterface>hardware_interface/EffortJointInterface</hardwareInterface>
      <mechanicalReduction>1</mechanicalReduction>
    </actuator>
  </transmission>
  <transmission name="Rev4_tran">
    <type>transmission_interface/SimpleTransmission</type>
    <joint name="Rev4">
      <hardwareInterface>hardware_interface/EffortJointInterface</hardwareInterface>
    </joint>
    <actuator name="Rev4_actr">
      <hardwareInterface>hardware_interface/EffortJointInterface</hardwareInterface>
      <mechanicalReduction>1</mechanicalReduction>
    </actuator>
  </transmission>
  <transmission name="Rev5_tran">
    <type>transmission_interface/SimpleTransmission</type>
    <joint name="Rev5">
      <hardwareInterface>hardware_interface/EffortJointInterface</hardwareInterface>
    </joint>
    <actuator name="Rev5_actr">
      <hardwareInterface>hardware_interface/EffortJointInterface</hardwareInterface>
      <mechanicalReduction>1</mechanicalReduction>
    </actuator>
  </transmission>
  <transmission name="Rev6_tran">
    <type>transmission_interface/SimpleTransmission</type>
    <joint name="Rev6">
      <hardwareInterface>hardware_interface/EffortJointInterface</hardwareInterface>
    </joint>
    <actuator name="Rev6_actr">
      <hardwareInterface>hardware_interface/EffortJointInterface</hardwareInterface>
      <mechanicalReduction>1</mechanicalReduction>
    </actuator>
  </transmission>
  <gazebo>
    <plugin filename="libgazebo_ros_control.so" name="control"/>
  </gazebo>
  <gazebo reference="base_link">
    <material>Gazebo/Silver</material>
    <mu1>0.2</mu1>
    <mu2>0.2</mu2>
    <selfCollide>true</selfCollide>
    <gravity>true</gravity>
  </gazebo>
  <gazebo reference="bottom_v1_1">
    <material>Gazebo/Silver</material>
    <mu1>0.2</mu1>
    <mu2>0.2</mu2>
    <selfCollide>true</selfCollide>
  </gazebo>
  <gazebo reference="Arm_1_v1_1">
    <material>Gazebo/Silver</material>
    <mu1>0.2</mu1>
    <mu2>0.2</mu2>
    <selfCollide>true</selfCollide>
  </gazebo>
  <gazebo reference="Arm_2_v1_1">
    <material>Gazebo/Silver</material>
    <mu1>0.2</mu1>
    <mu2>0.2</mu2>
    <selfCollide>true</selfCollide>
  </gazebo>
  <gazebo reference="neck_v1_1">
    <material>Gazebo/Silver</material>
    <mu1>0.2</mu1>
    <mu2>0.2</mu2>
    <selfCollide>true</selfCollide>
  </gazebo>
  <gazebo reference="head_v1_1">
    <material>Gazebo/Silver</material>
    <mu1>0.2</mu1>
    <mu2>0.2</mu2>
    <selfCollide>true</selfCollide>
  </gazebo>
  <gazebo reference="gripper_v1_1">
    <material>Gazebo/Silver</material>
    <mu1>0.2</mu1>
    <mu2>0.2</mu2>
    <selfCollide>true</selfCollide>
  </gazebo>
  <link name="base_link">
    <inertial>
      <origin rpy="0 0 0" xyz="0.009227173757711551 0.05711546040397183 -0.01795385944355127"/>
      <mass value="0.8137272025946127"/>
      <inertia ixx="0.000507" ixy="1e-06" ixz="-6e-06" iyy="0.000506" iyz="2e-06" izz="0.000865"/>
    </inertial>
    <visual>
      <origin rpy="0 0 0" xyz="0 0 0"/>
      <geometry>
        <mesh filename="package://Dynamixel_spot_arm_description/meshes/base_link.stl" scale="0.001 0.001 0.001"/>
      </geometry>
      <material name="silver"/>
    </visual>
    <collision>
      <origin rpy="0 0 0" xyz="0 0 0"/>
      <geometry>
        <mesh filename="package://Dynamixel_spot_arm_description/meshes/base_link.stl" scale="0.001 0.001 0.001"/>
      </geometry>
    </collision>
  </link>
  <link name="bottom_v1_1">
    <inertial>
      <origin rpy="0 0 0" xyz="4.3834423255225546e-05 1.851716180462093e-05 0.04608850485831119"/>
      <mass value="3.7768145403916407"/>
      <inertia ixx="0.003419" ixy="1e-06" ixz="7e-06" iyy="0.015468" iyz="3e-06" izz="0.014948"/>
    </inertial>
    <visual>
      <origin rpy="0 0 0" xyz="-0.009381 -0.055159 0.00311"/>
      <geometry>
        <mesh filename="package://Dynamixel_spot_arm_description/meshes/bottom_v1_1.stl" scale="0.001 0.001 0.001"/>
      </geometry>
      <material name="silver"/>
    </visual>
    <collision>
      <origin rpy="0 0 0" xyz="-0.009381 -0.055159 0.00311"/>
      <geometry>
        <mesh filename="package://Dynamixel_spot_arm_description/meshes/bottom_v1_1.stl" scale="0.001 0.001 0.001"/>
      </geometry>
    </collision>
  </link>
  <link name="Arm_1_v1_1">
    <inertial>
      <origin rpy="0 0 0" xyz="-0.03142910994215048 0.13773460820254285 -0.0002682558712496577"/>
      <mass value="4.3410244605972785"/>
      <inertia ixx="0.031102" ixy="6.4e-05" ixz="-0.0" iyy="0.002102" iyz="8.3e-05" izz="0.031758"/>
    </inertial>
    <visual>
      <origin rpy="0 0 0" xyz="-0.040881 -0.055159 -0.04679"/>
      <geometry>
        <mesh filename="package://Dynamixel_spot_arm_description/meshes/Arm_1_v1_1.stl" scale="0.001 0.001 0.001"/>
      </geometry>
      <material name="silver"/>
    </visual>
    <collision>
      <origin rpy="0 0 0" xyz="-0.040881 -0.055159 -0.04679"/>
      <geometry>
        <mesh filename="package://Dynamixel_spot_arm_description/meshes/Arm_1_v1_1.stl" scale="0.001 0.001 0.001"/>
      </geometry>
    </collision>
  </link>
  <link name="Arm_2_v1_1">
    <inertial>
      <origin rpy="0 0 0" xyz="-0.0400132980912803 -0.11087815619558039 0.05350854885453979"/>
      <mass value="4.446518989183043"/>
      <inertia ixx="0.031386" ixy="-0.000713" ixz="7.5e-05" iyy="0.004183" iyz="0.004183" izz="0.032487"/>
    </inertial>
    <visual>
      <origin rpy="0 0 0" xyz="-0.048281 -0.321159 -0.04679"/>
      <geometry>
        <mesh filename="package://Dynamixel_spot_arm_description/meshes/Arm_2_v1_1.stl" scale="0.001 0.001 0.001"/>
      </geometry>
      <material name="silver"/>
    </visual>
    <collision>
      <origin rpy="0 0 0" xyz="-0.048281 -0.321159 -0.04679"/>
      <geometry>
        <mesh filename="package://Dynamixel_spot_arm_description/meshes/Arm_2_v1_1.stl" scale="0.001 0.001 0.001"/>
      </geometry>
    </collision>
  </link>
  <link name="neck_v1_1">
    <inertial>
      <origin rpy="0 0 0" xyz="0.02091414181608834 -0.018445992362037696 0.00022304823726640444"/>
      <mass value="0.8026625496929148"/>
      <inertia ixx="0.000752" ixy="-3e-05" ixz="0.0" iyy="0.000408" iyz="4.8e-05" izz="0.000713"/>
    </inertial>
    <visual>
      <origin rpy="0 0 0" xyz="0.009769 -0.021298 -0.120135"/>
      <geometry>
        <mesh filename="package://Dynamixel_spot_arm_description/meshes/neck_v1_1.stl" scale="0.001 0.001 0.001"/>
      </geometry>
      <material name="silver"/>
    </visual>
    <collision>
      <origin rpy="0 0 0" xyz="0.009769 -0.021298 -0.120135"/>
      <geometry>
        <mesh filename="package://Dynamixel_spot_arm_description/meshes/neck_v1_1.stl" scale="0.001 0.001 0.001"/>
      </geometry>
    </collision>
  </link>
  <link name="head_v1_1">
    <inertial>
      <origin rpy="0 0 0" xyz="0.0005326054691075326 -0.05481950519531094 -0.00779651999716835"/>
      <mass value="1.2644309089007917"/>
      <inertia ixx="0.003243" ixy="3.8e-05" ixz="1.7e-05" iyy="0.001545" iyz="-0.000559" izz="0.002975"/>
    </inertial>
    <visual>
      <origin rpy="0 0 0" xyz="-0.00937 0.027862 -0.124436"/>
      <geometry>
        <mesh filename="package://Dynamixel_spot_arm_description/meshes/head_v1_1.stl" scale="0.001 0.001 0.001"/>
      </geometry>
      <material name="silver"/>
    </visual>
    <collision>
      <origin rpy="0 0 0" xyz="-0.00937 0.027862 -0.124436"/>
      <geometry>
        <mesh filename="package://Dynamixel_spot_arm_description/meshes/head_v1_1.stl" scale="0.001 0.001 0.001"/>
      </geometry>
    </collision>
  </link>
  <link name="gripper_v1_1">
    <inertial>
      <origin rpy="0 0 0" xyz="-0.032852931223272375 -0.04190244397153055 -0.015098287029036872"/>
      <mass value="0.8080491704220107"/>
      <inertia ixx="0.000715" ixy="0.0" ixz="0.0" iyy="0.000727" iyz="-0.000254" izz="0.000856"/>
    </inertial>
    <visual>
      <origin rpy="0 0 0" xyz="-0.044377 0.107781 -0.146383"/>
      <geometry>
        <mesh filename="package://Dynamixel_spot_arm_description/meshes/gripper_v1_1.stl" scale="0.001 0.001 0.001"/>
      </geometry>
      <material name="silver"/>
    </visual>
    <collision>
      <origin rpy="0 0 0" xyz="-0.044377 0.107781 -0.146383"/>
      <geometry>
        <mesh filename="package://Dynamixel_spot_arm_description/meshes/gripper_v1_1.stl" scale="0.001 0.001 0.001"/>
      </geometry>
    </collision>
  </link>
  <joint name="Rev1" type="revolute">
    <origin rpy="0 0 0" xyz="0.009381 0.055159 -0.00311"/>
    <parent link="base_link"/>
    <child link="bottom_v1_1"/>
    <axis xyz="0.0 0.0 -1.0"/>
  </joint>
  <joint name="Rev2" type="revolute">
    <origin rpy="0 0 0" xyz="0.0315 0.0 0.0499"/>
    <parent link="bottom_v1_1"/>
    <child link="Arm_1_v1_1"/>
    <axis xyz="1.0 -0.0 -0.0"/>
  </joint>
  <joint name="Rev3" type="revolute">
    <origin rpy="0 0 0" xyz="0.0074 0.266 0.0"/>
    <parent link="Arm_1_v1_1"/>
    <child link="Arm_2_v1_1"/>
    <axis xyz="-1.0 0.0 -0.0"/>
  </joint>
  <joint name="Rev4" type="revolute">
    <origin rpy="0 0 0" xyz="-0.05805 -0.299861 0.073345"/>
    <parent link="Arm_2_v1_1"/>
    <child link="neck_v1_1"/>
    <axis xyz="1.0 0.0 0.0"/>
  </joint>
  <joint name="Rev5" type="revolute">
    <origin rpy="0 0 0" xyz="0.019139 -0.04916 0.004301"/>
    <parent link="neck_v1_1"/>
    <child link="head_v1_1"/>
    <axis xyz="-0.0 -0.996195 0.087156"/>
  </joint>
  <joint name="Rev6" type="revolute">
    <origin rpy="0 0 0" xyz="0.035007 -0.079919 0.021947"/>
    <parent link="head_v1_1"/>
    <child link="gripper_v1_1"/>
    <axis xyz="-1.0 0.0 -0.0"/>
  </joint>
</robot>
